2025-10-02 12:16:30,355 - root - INFO - Logging configured successfully.
2025-10-02 12:16:30,355 - root - INFO - Log file created at: data/simulation_logs\simulation_20251002_121630.log
2025-10-02 12:16:30,355 - __main__ - INFO - Initializing Simulation (Layer 1)...
2025-10-02 12:16:30,356 - skymind_sim.layer_1_simulation.simulation - INFO - Simulation (Layer 1) initialized.
2025-10-02 12:16:30,356 - skymind_sim.layer_1_simulation.simulation - INFO - Attempting to load world from: data/maps/simple_map.json
2025-10-02 12:16:30,357 - skymind_sim.layer_1_simulation.simulation - INFO - World setup complete: 1 drone(s), 3 obstacle(s).
2025-10-02 12:16:30,358 - __main__ - INFO - World loaded successfully from file.
2025-10-02 12:16:30,358 - __main__ - CRITICAL - An unhandled exception occurred: 'Simulation' object has no attribute 'get_world'
Traceback (most recent call last):
  File "D:\Payannameh\SkyMind_Sim\skymind_sim\main.py", line 31, in main
    drone = simulation.get_world().get_drone_by_id('d1')
            ^^^^^^^^^^^^^^^^^^^^
AttributeError: 'Simulation' object has no attribute 'get_world'
2025-10-02 12:16:30,366 - __main__ - INFO - Application Closed
